#VRML_SIM R2023a utf8
PROTO FourWheelsRobot [
  field SFVec3f    translation  0 0 0
  field SFRotation rotation     0 0 1 0
  field SFFloat    bodyMass     1
]
{
  Robot {
  translation IS translation
  rotation IS rotation
  children [
    DistanceSensor {
      translation 0.1 0.025 0
      rotation 0 0 1 0.3926996938995747
      children [
        DEF sensor Shape {
          appearance PBRAppearance {
            baseColor 0 0 1
          }
          geometry Box {
            size 0.01 0.01 0.01
          }
        }
      ]
      name "df_left"
    }
    DistanceSensor {
      translation 0.1 -0.025 0
      rotation 0 0 1 -0.3927
      children [
        DEF sensor Shape {
          appearance PBRAppearance {
            baseColor 0 0 1
          }
          geometry Box {
            size 0.01 0.01 0.01
          }
        }
      ]
      name "df_right"
    }
    DEF BODY Shape {
      appearance PBRAppearance {
        baseColor 0.666667 0 0
      }
      geometry Box {
        size 0.2 0.1 0.05
      }
    }
    HingeJoint {
      jointParameters HingeJointParameters {
        position 6.963937558287895e-12
        axis 0 1 0
        anchor 0.05 0.06 0
      }
      device [
        RotationalMotor {
          name "wheel1"
        }
      ]
      endPoint DEF wheel1 Solid {
        translation 0.05 0.06 0
        rotation 1 3.4819559891819485e-12 -3.4819687791439475e-12 1.5708
        children [
          DEF roda Shape {
            appearance PBRAppearance {
            }
            geometry Cylinder {
              height 0.02
              radius 0.04
            }
          }
        ]
        boundingObject USE roda
        physics DEF wheel_ph Physics {
        }
        linearVelocity 2.737058232995287e-12 -1.5421688423641736e-14 7.235243684849343e-09
        angularVelocity -3.8011800788969216e-15 6.844186751262367e-11 1.4173292130135593e-16
      }
    }
    HingeJoint {
      jointParameters HingeJointParameters {
        position 6.964129825701895e-12
        axis 0 1 0
        anchor 0.05 -0.06 0
      }
      device [
        RotationalMotor {
          name "wheel2"
        }
      ]
      endPoint DEF wheel2 Solid {
        translation 0.05 -0.06 0
        rotation -1 3.48205212253583e-12 3.4820649128509473e-12 1.5708
        children [
          USE roda
        ]
        boundingObject USE roda
        physics USE wheel_ph
        linearVelocity 2.7370042757900675e-12 1.520656892026215e-14 7.235243537644288e-09
        angularVelocity 8.747954807029022e-15 6.843963167887296e-11 1.4162305078485375e-16
      }
    }
    HingeJoint {
      jointParameters HingeJointParameters {
        position 6.964314858221558e-12
        axis 0 1 0
        anchor -0.05 0.06 0
      }
      device [
        RotationalMotor {
          name "wheel3"
        }
      ]
      endPoint DEF wheel3 Solid {
        translation -0.05 0.06 0
        rotation 1 3.4821446384558316e-12 -3.482157429110779e-12 1.5708
        children [
          USE roda
        ]
        boundingObject USE roda
        physics USE wheel_ph
        linearVelocity 2.736923385959516e-12 -1.53850007614864e-14 7.2351252995403955e-09
        angularVelocity -3.1640509492615406e-15 6.843789494340857e-11 1.41732797131152e-16
      }
    }
    HingeJoint {
      jointParameters HingeJointParameters {
        position 6.964121623051676e-12
        axis 0 1 0
        anchor -0.05 -0.06 0
      }
      device [
        RotationalMotor {
          name "wheel4"
        }
      ]
      endPoint DEF wheel4 Solid {
        translation -0.05 -0.06 0
        rotation -1 3.482048021225786e-12 3.4820608115258384e-12 1.5708
        children [
          USE roda
        ]
        boundingObject USE roda
        physics USE wheel_ph
        linearVelocity 2.736971502644068e-12 1.543845759569508e-14 7.235125853130736e-09
        angularVelocity 5.0923214189828e-16 6.843948689285653e-11 1.4162224023701164e-16
      }
    }
  ]
  boundingObject USE BODY
  physics Physics {
    density -1
    mass IS bodyMass
  }
  controller "four_wheeled_collision_avoidance"
 }
}